<?xml version="1.0" ?>
<!-- =================================================================================== -->
<!-- |    This document was autogenerated by xacro from robots/ground_robot.xacro      | -->
<!-- |    EDITING THIS FILE BY HAND IS NOT RECOMMENDED                                 | -->
<!-- =================================================================================== -->
<robot name="ground_robot">
  <!-- Base link -->
  <link name="base_link">
    <visual>
      <geometry>
        <box size="0.8 0.6 0.1"/>
      </geometry>
      <material name="blue"/>
    </visual>
    <collision>
      <geometry>
        <box size="0.8 0.6 0.1"/>
      </geometry>
    </collision>
    <inertial>
      <mass value="0.5"/>
      <origin rpy="0 0 0" xyz="0.4 0 0"/>
      <inertia ixx="0.1" ixy="0.0" ixz="0.0" iyy="0.1" iyz="0.0" izz="0.1"/>
    </inertial>
  </link>
  <link name="marker">
    <inertial>
      <origin rpy="0.0 0.0 0.0" xyz="0.0 0.0 0.0"/>
      <mass value="0.0001"/>
      <inertia ixx="0.00" ixy="0.0" ixz="0.0" iyy="0.0" iyz="0.0" izz="0.0001"/>
    </inertial>
    <visual name="marker">
      <origin rpy="0.0 -1.570796327 0.0"/>
      <geometry>
        <mesh filename="/home/sulieman/quadrotor_target_tracking/install/robots_description/share/robots_description/meshes/Marker0.obj" scale="1.0 1.0 1.0"/>
      </geometry>
    </visual>
  </link>
  <joint name="aruco" type="fixed">
    <parent link="base_link"/>
    <child link="marker"/>
    <origin rpy="0 0 0" xyz="0 -0.3 0.060000000000000005"/>
  </joint>
  <link name="wheel_front_left">
    <visual>
      <geometry>
        <cylinder length="0.05" radius="0.1"/>
      </geometry>
      <material name="black"/>
    </visual>
    <collision>
      <geometry>
        <cylinder length="0.05" radius="0.1"/>
      </geometry>
    </collision>
    <inertial>
      <mass value="0.1"/>
      <origin rpy="0 0 0" xyz="0 0 0"/>
      <inertia ixx="0.01" ixy="0.0" ixz="0.0" iyy="0.01" iyz="0.0" izz="0.01"/>
    </inertial>
  </link>
  <joint name="wheel_front_left_joint" type="continuous">
    <parent link="base_link"/>
    <child link="wheel_front_left"/>
    <origin rpy="1.5708 0 0" xyz="0.4 0.3 -0.1"/>
    <axis xyz="0 0 -1"/>
  </joint>
  <link name="wheel_front_right">
    <visual>
      <geometry>
        <cylinder length="0.05" radius="0.1"/>
      </geometry>
      <material name="black"/>
    </visual>
    <collision>
      <geometry>
        <cylinder length="0.05" radius="0.1"/>
      </geometry>
    </collision>
    <inertial>
      <mass value="0.1"/>
      <origin rpy="0 0 0" xyz="0 0 0"/>
      <inertia ixx="0.01" ixy="0.0" ixz="0.0" iyy="0.01" iyz="0.0" izz="0.01"/>
    </inertial>
  </link>
  <joint name="wheel_front_right_joint" type="continuous">
    <parent link="base_link"/>
    <child link="wheel_front_right"/>
    <origin rpy="1.5708 0 0" xyz="0.4 -0.3 -0.1"/>
    <axis xyz="0 0 -1"/>
  </joint>
  <link name="wheel_back_left">
    <visual>
      <geometry>
        <cylinder length="0.05" radius="0.1"/>
      </geometry>
      <material name="black"/>
    </visual>
    <collision>
      <geometry>
        <cylinder length="0.05" radius="0.1"/>
      </geometry>
    </collision>
    <inertial>
      <mass value="0.1"/>
      <origin rpy="0 0 0" xyz="0 0 0"/>
      <inertia ixx="0.01" ixy="0.0" ixz="0.0" iyy="0.01" iyz="0.0" izz="0.01"/>
    </inertial>
  </link>
  <joint name="wheel_back_left_joint" type="continuous">
    <parent link="base_link"/>
    <child link="wheel_back_left"/>
    <origin rpy="1.5708 0 0" xyz="-0.4 0.3 -0.1"/>
    <axis xyz="0 0 -1"/>
  </joint>
  <link name="wheel_back_right">
    <visual>
      <geometry>
        <cylinder length="0.05" radius="0.1"/>
      </geometry>
      <material name="black"/>
    </visual>
    <collision>
      <geometry>
        <cylinder length="0.05" radius="0.1"/>
      </geometry>
    </collision>
    <inertial>
      <mass value="0.1"/>
      <origin rpy="0 0 0" xyz="0 0 0"/>
      <inertia ixx="0.01" ixy="0.0" ixz="0.0" iyy="0.01" iyz="0.0" izz="0.01"/>
    </inertial>
  </link>
  <joint name="wheel_back_right_joint" type="continuous">
    <parent link="base_link"/>
    <child link="wheel_back_right"/>
    <origin rpy="1.5708 0 0" xyz="-0.4 -0.3 -0.1"/>
    <axis xyz="0 0 -1"/>
  </joint>
  <!-- Differential Drive Plugin -->
  <!-- <gazebo>
    <plugin name="diff_drive_controller" filename="libgazebo_ros_diff_drive.so">
      <alwaysOn>true</alwaysOn>
      <updateRate>100.0</updateRate>
      <wheelSeparation>${base_width}</wheelSeparation>
      <wheelDiameter>${wheel_radius * 2}</wheelDiameter>
      <wheelTorque>5.0</wheelTorque>
      <commandTopic>/cmd_vel</commandTopic>
      <odometryTopic>/odom</odometryTopic>
      <odometryFrame>odom</odometryFrame>
      <robotBaseFrame>base_link</robotBaseFrame>
      <publishTf>true</publishTf>
      <leftJoint>wheel_front_left_joint</leftJoint>
      <rightJoint>wheel_front_right_joint</rightJoint>
    </plugin>
  </gazebo> -->
  <gazebo>
    <plugin filename="libgazebo_ros_diff_drive.so" name="wheel_drive_controller">
      <!-- wheels -->
      <num_wheel_pairs>2</num_wheel_pairs>
      <left_joint>wheel_front_left_joint</left_joint>
      <right_joint>wheel_front_right_joint</right_joint>
      <left_joint>wheel_back_left_joint</left_joint>
      <right_joint>wheel_back_right_joint</right_joint>
      <!-- kinematics -->
      <wheel_separation>0.6</wheel_separation>
      <wheel_diameter>0.2</wheel_diameter>
      <!-- Limits -->
      <max_wheel_torque>200.0</max_wheel_torque>
      <max_wheel_acceleration>10.0</max_wheel_acceleration>
      <!-- Output -->
      <odometry_frame>odom</odometry_frame>
      <robot_base_frame>base_link</robot_base_frame>
      <!-- topic & re remappings -->
      <ros>
        <namespace>/ground_robot</namespace>
        <argument>/cmd_vel:=cmd_vel</argument>
        <argument>/odom:=odom</argument>
      </ros>
      <publish_odom>true</publish_odom>
      <publish_odom_tf>true</publish_odom_tf>
      <update_rate>100.0</update_rate>
    </plugin>
  </gazebo>
  <gazebo reference="base_link">
    <material>Gazebo/Green</material>
  </gazebo>
</robot>
